[2023-11-24 22:53:29,758] ERROR log_exception() L1449 Exception on /raa [GET] - call_trace=/Users/tairik/PycharmProjects/mvp-tairik/venv/lib/python3.9/site-packages/flask/app.py L1449
Traceback (most recent call last):
  File "/Users/tairik/PycharmProjects/mvp-tairik/venv/lib/python3.9/site-packages/flask/app.py", line 2073, in wsgi_app
    response = self.full_dispatch_request()
  File "/Users/tairik/PycharmProjects/mvp-tairik/venv/lib/python3.9/site-packages/flask/app.py", line 1519, in full_dispatch_request
    rv = self.handle_user_exception(e)
  File "/Users/tairik/PycharmProjects/mvp-tairik/venv/lib/python3.9/site-packages/flask_cors/extension.py", line 165, in wrapped_function
    return cors_after_request(app.make_response(f(*args, **kwargs)))
  File "/Users/tairik/PycharmProjects/mvp-tairik/venv/lib/python3.9/site-packages/flask/app.py", line 1517, in full_dispatch_request
    rv = self.dispatch_request()
  File "/Users/tairik/PycharmProjects/mvp-tairik/venv/lib/python3.9/site-packages/flask/app.py", line 1503, in dispatch_request
    return self.ensure_sync(self.view_functions[rule.endpoint])(**req.view_args)
  File "/Users/tairik/PycharmProjects/mvp-tairik/venv/lib/python3.9/site-packages/flask_openapi3/scaffold.py", line 109, in wrapper
    resp = _do_wrapper(
  File "/Users/tairik/PycharmProjects/mvp-tairik/venv/lib/python3.9/site-packages/flask_openapi3/do_wrapper.py", line 135, in _do_wrapper
    response = func(**request_kwargs)
  File "/Users/tairik/PycharmProjects/mvp-tairik/rest_api_pets/app.py", line 64, in get_raa
    return (prediction), 200
  File "/Users/tairik/PycharmProjects/mvp-tairik/rest_api_pets/schemas/dog.py", line 38, in apresenta_raa
    "id": dog.id,
AttributeError: 'numpy.ndarray' object has no attribute 'id'
[2023-11-24 22:53:29,826] INFO _log() L224  192.168.68.102 - - [24/Nov/2023 22:53:29] "[35m[1mGET /raa HTTP/1.1[0m" 500 - - call_trace=/Users/tairik/PycharmProjects/mvp-tairik/venv/lib/python3.9/site-packages/werkzeug/_internal.py L224 
[2023-11-24 22:53:31,008] ERROR log_exception() L1449 Exception on /raa [GET] - call_trace=/Users/tairik/PycharmProjects/mvp-tairik/venv/lib/python3.9/site-packages/flask/app.py L1449
Traceback (most recent call last):
  File "/Users/tairik/PycharmProjects/mvp-tairik/venv/lib/python3.9/site-packages/flask/app.py", line 2073, in wsgi_app
    response = self.full_dispatch_request()
  File "/Users/tairik/PycharmProjects/mvp-tairik/venv/lib/python3.9/site-packages/flask/app.py", line 1519, in full_dispatch_request
    rv = self.handle_user_exception(e)
  File "/Users/tairik/PycharmProjects/mvp-tairik/venv/lib/python3.9/site-packages/flask_cors/extension.py", line 165, in wrapped_function
    return cors_after_request(app.make_response(f(*args, **kwargs)))
  File "/Users/tairik/PycharmProjects/mvp-tairik/venv/lib/python3.9/site-packages/flask/app.py", line 1517, in full_dispatch_request
    rv = self.dispatch_request()
  File "/Users/tairik/PycharmProjects/mvp-tairik/venv/lib/python3.9/site-packages/flask/app.py", line 1503, in dispatch_request
    return self.ensure_sync(self.view_functions[rule.endpoint])(**req.view_args)
  File "/Users/tairik/PycharmProjects/mvp-tairik/venv/lib/python3.9/site-packages/flask_openapi3/scaffold.py", line 109, in wrapper
    resp = _do_wrapper(
  File "/Users/tairik/PycharmProjects/mvp-tairik/venv/lib/python3.9/site-packages/flask_openapi3/do_wrapper.py", line 135, in _do_wrapper
    response = func(**request_kwargs)
  File "/Users/tairik/PycharmProjects/mvp-tairik/rest_api_pets/app.py", line 64, in get_raa
    return (prediction), 200
  File "/Users/tairik/PycharmProjects/mvp-tairik/rest_api_pets/schemas/dog.py", line 38, in apresenta_raa
    "id": dog.id,
AttributeError: 'numpy.ndarray' object has no attribute 'id'
[2023-11-24 22:53:31,010] INFO _log() L224  192.168.68.102 - - [24/Nov/2023 22:53:31] "[35m[1mGET /raa HTTP/1.1[0m" 500 - - call_trace=/Users/tairik/PycharmProjects/mvp-tairik/venv/lib/python3.9/site-packages/werkzeug/_internal.py L224 
[2023-11-24 22:53:38,269] INFO _log() L224   * Running on all addresses (0.0.0.0)
   WARNING: This is a development server. Do not use it in a production deployment.
 * Running on http://127.0.0.1:4001
 * Running on http://192.168.68.102:4001 (Press CTRL+C to quit) - call_trace=/Users/tairik/PycharmProjects/mvp-tairik/venv/lib/python3.9/site-packages/werkzeug/_internal.py L224 
[2023-11-24 22:53:40,585] ERROR log_exception() L1449 Exception on /raa [GET] - call_trace=/Users/tairik/PycharmProjects/mvp-tairik/venv/lib/python3.9/site-packages/flask/app.py L1449
Traceback (most recent call last):
  File "/Users/tairik/PycharmProjects/mvp-tairik/venv/lib/python3.9/site-packages/flask/app.py", line 2073, in wsgi_app
    response = self.full_dispatch_request()
  File "/Users/tairik/PycharmProjects/mvp-tairik/venv/lib/python3.9/site-packages/flask/app.py", line 1520, in full_dispatch_request
    return self.finalize_request(rv)
  File "/Users/tairik/PycharmProjects/mvp-tairik/venv/lib/python3.9/site-packages/flask/app.py", line 1539, in finalize_request
    response = self.make_response(rv)
  File "/Users/tairik/PycharmProjects/mvp-tairik/venv/lib/python3.9/site-packages/flask/app.py", line 1730, in make_response
    raise TypeError(
TypeError: The view function did not return a valid response. The return type must be a string, dict, tuple, Response instance, or WSGI callable, but it was a ndarray.
[2023-11-24 22:53:40,590] INFO _log() L224  192.168.68.102 - - [24/Nov/2023 22:53:40] "[35m[1mGET /raa HTTP/1.1[0m" 500 - - call_trace=/Users/tairik/PycharmProjects/mvp-tairik/venv/lib/python3.9/site-packages/werkzeug/_internal.py L224 
[2023-11-24 22:53:41,550] ERROR log_exception() L1449 Exception on /raa [GET] - call_trace=/Users/tairik/PycharmProjects/mvp-tairik/venv/lib/python3.9/site-packages/flask/app.py L1449
Traceback (most recent call last):
  File "/Users/tairik/PycharmProjects/mvp-tairik/venv/lib/python3.9/site-packages/flask/app.py", line 2073, in wsgi_app
    response = self.full_dispatch_request()
  File "/Users/tairik/PycharmProjects/mvp-tairik/venv/lib/python3.9/site-packages/flask/app.py", line 1520, in full_dispatch_request
    return self.finalize_request(rv)
  File "/Users/tairik/PycharmProjects/mvp-tairik/venv/lib/python3.9/site-packages/flask/app.py", line 1539, in finalize_request
    response = self.make_response(rv)
  File "/Users/tairik/PycharmProjects/mvp-tairik/venv/lib/python3.9/site-packages/flask/app.py", line 1730, in make_response
    raise TypeError(
TypeError: The view function did not return a valid response. The return type must be a string, dict, tuple, Response instance, or WSGI callable, but it was a ndarray.
[2023-11-24 22:53:41,551] INFO _log() L224  192.168.68.102 - - [24/Nov/2023 22:53:41] "[35m[1mGET /raa HTTP/1.1[0m" 500 - - call_trace=/Users/tairik/PycharmProjects/mvp-tairik/venv/lib/python3.9/site-packages/werkzeug/_internal.py L224 
[2023-11-24 22:54:35,466] INFO _log() L224   * Running on all addresses (0.0.0.0)
   WARNING: This is a development server. Do not use it in a production deployment.
 * Running on http://127.0.0.1:4001
 * Running on http://192.168.68.102:4001 (Press CTRL+C to quit) - call_trace=/Users/tairik/PycharmProjects/mvp-tairik/venv/lib/python3.9/site-packages/werkzeug/_internal.py L224 
[2023-11-24 22:54:36,277] ERROR log_exception() L1449 Exception on /raa [GET] - call_trace=/Users/tairik/PycharmProjects/mvp-tairik/venv/lib/python3.9/site-packages/flask/app.py L1449
Traceback (most recent call last):
  File "/Users/tairik/PycharmProjects/mvp-tairik/venv/lib/python3.9/site-packages/flask/app.py", line 2073, in wsgi_app
    response = self.full_dispatch_request()
  File "/Users/tairik/PycharmProjects/mvp-tairik/venv/lib/python3.9/site-packages/flask/app.py", line 1520, in full_dispatch_request
    return self.finalize_request(rv)
  File "/Users/tairik/PycharmProjects/mvp-tairik/venv/lib/python3.9/site-packages/flask/app.py", line 1539, in finalize_request
    response = self.make_response(rv)
  File "/Users/tairik/PycharmProjects/mvp-tairik/venv/lib/python3.9/site-packages/flask/app.py", line 1730, in make_response
    raise TypeError(
TypeError: The view function did not return a valid response. The return type must be a string, dict, tuple, Response instance, or WSGI callable, but it was a int64.
[2023-11-24 22:54:36,282] INFO _log() L224  192.168.68.102 - - [24/Nov/2023 22:54:36] "[35m[1mGET /raa HTTP/1.1[0m" 500 - - call_trace=/Users/tairik/PycharmProjects/mvp-tairik/venv/lib/python3.9/site-packages/werkzeug/_internal.py L224 
[2023-11-24 22:54:37,425] ERROR log_exception() L1449 Exception on /raa [GET] - call_trace=/Users/tairik/PycharmProjects/mvp-tairik/venv/lib/python3.9/site-packages/flask/app.py L1449
Traceback (most recent call last):
  File "/Users/tairik/PycharmProjects/mvp-tairik/venv/lib/python3.9/site-packages/flask/app.py", line 2073, in wsgi_app
    response = self.full_dispatch_request()
  File "/Users/tairik/PycharmProjects/mvp-tairik/venv/lib/python3.9/site-packages/flask/app.py", line 1520, in full_dispatch_request
    return self.finalize_request(rv)
  File "/Users/tairik/PycharmProjects/mvp-tairik/venv/lib/python3.9/site-packages/flask/app.py", line 1539, in finalize_request
    response = self.make_response(rv)
  File "/Users/tairik/PycharmProjects/mvp-tairik/venv/lib/python3.9/site-packages/flask/app.py", line 1730, in make_response
    raise TypeError(
TypeError: The view function did not return a valid response. The return type must be a string, dict, tuple, Response instance, or WSGI callable, but it was a int64.
[2023-11-24 22:54:37,427] INFO _log() L224  192.168.68.102 - - [24/Nov/2023 22:54:37] "[35m[1mGET /raa HTTP/1.1[0m" 500 - - call_trace=/Users/tairik/PycharmProjects/mvp-tairik/venv/lib/python3.9/site-packages/werkzeug/_internal.py L224 
